<?xml version="1.0" ?>
<!-- =================================================================================== -->
<!-- |    This document was autogenerated by xacro from veh_model.urdf.xacro           | -->
<!-- |    EDITING THIS FILE BY HAND IS NOT RECOMMENDED                                 | -->
<!-- =================================================================================== -->
<!-- veh_model.urdf.xacro

This file defines a model of a generic ackermann steered vehicle

Lengths are measured in meters, angles are measured in radians, and masses are
measured in kilograms. All of these values are approximations.

To work with Gazebo, each link must have an inertial element, even if
the link only serves to connect two joints. To be visible in Gazebo, a link
must have a collision element. Furthermore, the link must have a Gazebo
material.

Copyright (c) 2022-2022 John Deere Pvt. Limited, India


-->
<robot name="em_3905">
  <material name="chassis_mat">
    <color rgba="0.5 1 0.5 1"/>
  </material>
  <material name="tire_mat">
    <color rgba="0 0 0 1"/>
  </material>
  <!-- base_link must have geometry so that its axes can be displayed in
       rviz. -->
  <link name="base_link">
    <visual>
      <geometry>
        <box size="0.01 0.01 0.01"/>
      </geometry>
      <material name="chassis_mat"/>
    </visual>
  </link>
  <gazebo reference="base_link">
    <material>Gazebo/Grey</material>
  </gazebo>
  <!-- Chassis -->
  <link name="chassis">
    <visual>
      <origin xyz="0 0 -0.025"/>
      <geometry>
        <box size="0.5 0.3 0.05"/>
      </geometry>
      <material name="chassis_mat"/>
    </visual>
    <collision>
      <origin xyz="0 0 -0.025"/>
      <geometry>
        <box size="0.5 0.3 0.05"/>
      </geometry>
    </collision>
    <inertial>
      <origin xyz="0 0 -0.025"/>
      <mass value="4"/>
      <inertia ixx="0.030833333333333334" ixy="0" ixz="0" iyy="0.08416666666666667" iyz="0" izz="0.11333333333333333"/>
    </inertial>
  </link>
  <gazebo reference="chassis">
    <material>Gazebo/Grey</material>
  </gazebo>
  <joint name="base_link_to_chassis" type="fixed">
    <parent link="base_link"/>
    <child link="chassis"/>
  </joint>
  <joint name="left_front_shock" type="prismatic">
    <parent link="chassis"/>
    <child link="left_steering_link"/>
    <origin xyz="0.3                    0.22                    0.020000000000000004"/>
    <axis xyz="0 0 -1"/>
    <limit effort="12" lower="-0.05" upper="0.05" velocity="1000"/>
  </joint>
  <link name="left_steering_link">
    <inertial>
      <mass value="0.001"/>
      <inertia ixx="0.001" ixy="0" ixz="0" iyy="0.001" iyz="0" izz="0.001"/>
    </inertial>
  </link>
  <joint name="left_steering_joint" type="revolute">
    <parent link="left_steering_link"/>
    <child link="left_front_axle_carrier"/>
    <axis xyz="0 0 1"/>
    <limit effort="0.5" lower="-0.7853981633974483" upper="0.7853981633974483" velocity="4.5"/>
  </joint>
  <link name="left_front_axle_carrier">
    <inertial>
      <mass value="0.001"/>
      <inertia ixx="0.001" ixy="0" ixz="0" iyy="0.001" iyz="0" izz="0.001"/>
    </inertial>
  </link>
  <!-- The left and right axles have the same axis so that identical
         rotation values cause the wheels to rotate in the same direction. -->
  <joint name="left_front_axle" type="continuous">
    <parent link="left_front_axle_carrier"/>
    <child link="left_front_wheel"/>
    <origin rpy="1.5707963267948966 0 0"/>
    <axis xyz="0 0 -1"/>
    <limit effort="5" velocity="250"/>
  </joint>
  <link name="left_front_wheel">
    <visual>
      <origin xyz="0                      -3.469446951953614e-18                      0"/>
      <geometry>
        <cylinder length="0.1" radius="0.1"/>
      </geometry>
      <material name="tire_mat"/>
    </visual>
    <collision>
      <origin xyz="0                      -3.469446951953614e-18                      0"/>
      <geometry>
        <cylinder length="0.1" radius="0.1"/>
      </geometry>
    </collision>
    <inertial>
      <mass value="0.5"/>
      <inertia ixx="0.0023697916666666667" ixy="0" ixz="0" iyy="0.0023697916666666667" iyz="0" izz="0.00390625"/>
    </inertial>
  </link>
  <gazebo reference="left_front_wheel">
    <material>Gazebo/Black</material>
  </gazebo>
  <joint name="right_front_shock" type="prismatic">
    <parent link="chassis"/>
    <child link="right_steering_link"/>
    <origin xyz="0.3                    -0.22                    0.020000000000000004"/>
    <axis xyz="0 0 -1"/>
    <limit effort="12" lower="-0.05" upper="0.05" velocity="1000"/>
  </joint>
  <link name="right_steering_link">
    <inertial>
      <mass value="0.001"/>
      <inertia ixx="0.001" ixy="0" ixz="0" iyy="0.001" iyz="0" izz="0.001"/>
    </inertial>
  </link>
  <joint name="right_steering_joint" type="revolute">
    <parent link="right_steering_link"/>
    <child link="right_front_axle_carrier"/>
    <axis xyz="0 0 1"/>
    <limit effort="0.5" lower="-0.7853981633974483" upper="0.7853981633974483" velocity="4.5"/>
  </joint>
  <link name="right_front_axle_carrier">
    <inertial>
      <mass value="0.001"/>
      <inertia ixx="0.001" ixy="0" ixz="0" iyy="0.001" iyz="0" izz="0.001"/>
    </inertial>
  </link>
  <!-- The left and right axles have the same axis so that identical
         rotation values cause the wheels to rotate in the same direction. -->
  <joint name="right_front_axle" type="continuous">
    <parent link="right_front_axle_carrier"/>
    <child link="right_front_wheel"/>
    <origin rpy="1.5707963267948966 0 0"/>
    <axis xyz="0 0 -1"/>
    <limit effort="5" velocity="250"/>
  </joint>
  <link name="right_front_wheel">
    <visual>
      <origin xyz="0                      3.469446951953614e-18                      0"/>
      <geometry>
        <cylinder length="0.1" radius="0.1"/>
      </geometry>
      <material name="tire_mat"/>
    </visual>
    <collision>
      <origin xyz="0                      3.469446951953614e-18                      0"/>
      <geometry>
        <cylinder length="0.1" radius="0.1"/>
      </geometry>
    </collision>
    <inertial>
      <mass value="0.5"/>
      <inertia ixx="0.0023697916666666667" ixy="0" ixz="0" iyy="0.0023697916666666667" iyz="0" izz="0.00390625"/>
    </inertial>
  </link>
  <gazebo reference="right_front_wheel">
    <material>Gazebo/Black</material>
  </gazebo>
  <joint name="left_rear_shock" type="prismatic">
    <parent link="chassis"/>
    <child link="left_rear_axle_carrier"/>
    <origin xyz="-0.3                    0.22                    0.020000000000000004"/>
    <axis xyz="0 0 -1"/>
    <limit effort="12" lower="-0.05" upper="0.05" velocity="1000"/>
  </joint>
  <link name="left_rear_axle_carrier">
    <inertial>
      <mass value="0.001"/>
      <inertia ixx="0.001" ixy="0" ixz="0" iyy="0.001" iyz="0" izz="0.001"/>
    </inertial>
  </link>
  <!-- The left and right axles have the same axis so that identical
         rotation values cause the wheels to rotate in the same direction. -->
  <joint name="left_rear_axle" type="continuous">
    <parent link="left_rear_axle_carrier"/>
    <child link="left_rear_wheel"/>
    <origin rpy="1.5707963267948966 0 0"/>
    <axis xyz="0 0 -1"/>
    <limit effort="5" velocity="250"/>
  </joint>
  <link name="left_rear_wheel">
    <visual>
      <origin xyz="0                      -3.469446951953614e-18                      0"/>
      <geometry>
        <cylinder length="0.1" radius="0.1"/>
      </geometry>
      <material name="tire_mat"/>
    </visual>
    <collision>
      <origin xyz="0                      -3.469446951953614e-18                      0"/>
      <geometry>
        <cylinder length="0.1" radius="0.1"/>
      </geometry>
    </collision>
    <inertial>
      <mass value="0.5"/>
      <inertia ixx="0.0023697916666666667" ixy="0" ixz="0" iyy="0.0023697916666666667" iyz="0" izz="0.00390625"/>
    </inertial>
  </link>
  <gazebo reference="left_rear_wheel">
    <material>Gazebo/Black</material>
  </gazebo>
  <joint name="right_rear_shock" type="prismatic">
    <parent link="chassis"/>
    <child link="right_rear_axle_carrier"/>
    <origin xyz="-0.3                    -0.22                    0.020000000000000004"/>
    <axis xyz="0 0 -1"/>
    <limit effort="12" lower="-0.05" upper="0.05" velocity="1000"/>
  </joint>
  <link name="right_rear_axle_carrier">
    <inertial>
      <mass value="0.001"/>
      <inertia ixx="0.001" ixy="0" ixz="0" iyy="0.001" iyz="0" izz="0.001"/>
    </inertial>
  </link>
  <!-- The left and right axles have the same axis so that identical
         rotation values cause the wheels to rotate in the same direction. -->
  <joint name="right_rear_axle" type="continuous">
    <parent link="right_rear_axle_carrier"/>
    <child link="right_rear_wheel"/>
    <origin rpy="1.5707963267948966 0 0"/>
    <axis xyz="0 0 -1"/>
    <limit effort="5" velocity="250"/>
  </joint>
  <link name="right_rear_wheel">
    <visual>
      <origin xyz="0                      3.469446951953614e-18                      0"/>
      <geometry>
        <cylinder length="0.1" radius="0.1"/>
      </geometry>
      <material name="tire_mat"/>
    </visual>
    <collision>
      <origin xyz="0                      3.469446951953614e-18                      0"/>
      <geometry>
        <cylinder length="0.1" radius="0.1"/>
      </geometry>
    </collision>
    <inertial>
      <mass value="0.5"/>
      <inertia ixx="0.0023697916666666667" ixy="0" ixz="0" iyy="0.0023697916666666667" iyz="0" izz="0.00390625"/>
    </inertial>
  </link>
  <gazebo reference="right_rear_wheel">
    <material>Gazebo/Black</material>
  </gazebo>
  <gazebo>
    <plugin filename="libgazebo_ros_control.so" name="gazebo_ros_control"/>
  </gazebo>
</robot>
